<?xml version="1.0" encoding="utf-8"?>
<robot xmlns:xacro="http://www.ros.org/wiki/xacro">

  <xacro:macro name="leo" 
               params="default_antenna:=true
                       rockers_fixed:=true
                       footprint_link:=true
                       link_prefix:=''
                       joint_prefix:=''
                       imu_translation:='0.0628 -0.0314 -0.0393'">

    <xacro:macro name="rocker_link" params="name">
      <link name="${link_prefix}rocker_${name}_link">
        <inertial>
          <mass value="1.387336"/>
          <origin xyz="0 0.01346 -0.06506"/>
          <inertia
            ixx="0.002956" ixy="-0.000001489324" ixz="-0.000008103407"
            iyy="0.02924"  iyz="0.00007112"
            izz="0.02832"/>
        </inertial>
        <visual>
          <geometry>
            <mesh filename="package://leorover_description/models/Rocker.dae"/>
          </geometry>
        </visual>
        <collision>
          <geometry>
            <mesh filename="package://leorover_description/models/Rocker_outline.stl"/>
          </geometry>
        </collision>
      </link>
    </xacro:macro>

    <xacro:macro name="wheel_link" params="name model"> 
      <link name="${link_prefix}wheel_${name}_link">
        <inertial>
          <mass value="0.283642"/>
          <origin xyz="0 0.030026 0"/>
          <inertia
            ixx="0.000391"  ixy="0.00000123962" ixz="5.52582e-7"
            iyy="0.0004716" iyz="-0.000002082042"
            izz="0.000391"/>
        </inertial>
        <visual>
          <geometry>
            <mesh filename="package://leorover_description/models/Wheel${model}.dae"/>
          </geometry>
        </visual>
        <collision>
          <origin xyz="0 0.04485 0" rpy="${pi/2} 0 0"/>
          <geometry>
            <cylinder radius="0.057" length="0.07"/>
          </geometry>
        </collision>
        <collision>
          <origin xyz="0 0.04485 0" rpy="${pi/2} 0 0"/>
          <geometry>
            <cylinder radius="0.0625" length="0.04"/>
          </geometry>
        </collision>
        <collision>
          <geometry>
            <mesh filename="package://leorover_description/models/Wheel_outline.stl"/>
          </geometry>
        </collision>
      </link>
    </xacro:macro>

    <!-- LINKS -->
    <xacro:if value="${footprint_link}">
      <link name="${link_prefix}base_footprint"/>
    </xacro:if>

    <link name="${link_prefix}base_link">
      <inertial>
        <mass value="1.584994"/>
        <origin xyz="-0.019662 0.011643 -0.031802"/>
        <inertia
          ixx="0.01042" ixy="0.001177" ixz="-0.0008871"
          iyy="0.01045" iyz="0.0002226"
          izz="0.01817"/>
      </inertial>
      <visual>
        <geometry>
          <mesh filename="package://leorover_description/models/Chassis.dae"/>
        </geometry>
      </visual>
      <collision>
        <geometry>
          <mesh filename="package://leorover_description/models/Chassis_outline.stl"/>
        </geometry>
      </collision>
    </link>

    <xacro:rocker_link name="L"/>
    <xacro:rocker_link name="R"/>
    <xacro:wheel_link name="FL" model="A"/>
    <xacro:wheel_link name="RL" model="A"/>
    <xacro:wheel_link name="FR" model="B"/>
    <xacro:wheel_link name="RR" model="B"/>

    <xacro:if value="${default_antenna}">
      <link name="${link_prefix}antenna_link">
        <inertial>
          <mass value="0.001237"/>
          <origin xyz="0 0 0.028828"/>
          <inertia
            ixx="2.5529e-7" ixy="0.0" ixz="0.0"
            iyy="2.5529e-7" iyz="0.0"
            izz="1.354e-8"/>
        </inertial>
        <visual>
          <geometry>
            <mesh filename="package://leorover_description/models/Antenna.dae"/>
          </geometry>
        </visual>
        <collision>
          <origin xyz="0 0 0.028"/>
          <geometry>
            <cylinder radius="0.0055" length="0.056"/>
          </geometry>
        </collision>
      </link>
    </xacro:if>

    <link name="${link_prefix}camera_frame"/>
    <link name="${link_prefix}camera_optical_frame"/>
    <link name="${link_prefix}imu_frame"/>

    <!-- JOINTS -->

    <xacro:if value="${footprint_link}">
      <joint name="${joint_prefix}base_joint" type="fixed">
        <origin xyz="0 0 0.19783" rpy="0 0 0"/>
        <parent link="${link_prefix}base_footprint"/>
        <child link="${link_prefix}base_link"/>
      </joint>
    </xacro:if>

    <xacro:if value="${rockers_fixed}">
      <xacro:property name="rockers_joint_type" value="fixed"/>
    </xacro:if>
    <xacro:unless value="${rockers_fixed}">
      <xacro:property name="rockers_joint_type" value="revolute"/>
    </xacro:unless>

    <joint name="${joint_prefix}rocker_L_joint" type="${rockers_joint_type}">
      <origin xyz="0.00263 0.14167 -0.04731" rpy="0 0 ${pi}"/>
      <parent link="${link_prefix}base_link"/>
      <child link="${link_prefix}rocker_L_link"/>
      <axis xyz="0 1 0"/>
      <limit effort="100.0" lower="-0.24" upper="0.24" velocity="100.0"/>
      <dynamics friction="1.0" damping="0.1"/>
    </joint>

    <joint name="${joint_prefix}rocker_R_joint" type="${rockers_joint_type}">
      <origin xyz="0.00263 -0.14167 -0.04731" rpy="0 0 0"/>
      <parent link="${link_prefix}base_link"/>
      <child link="${link_prefix}rocker_R_link"/>
      <axis xyz="0 1 0"/>
      <limit effort="100.0" lower="-0.24" upper="0.24" velocity="100.0"/>
      <dynamics friction="1.0" damping="0.1"/> 
      <mimic joint="rocker_L_joint"/>
    </joint>

    <joint name="${joint_prefix}wheel_FL_joint" type="continuous">
      <origin xyz="-0.15256 -0.08214 -0.08802" rpy="0 0 0"/>
      <parent link="${link_prefix}rocker_L_link"/>
      <child link="${link_prefix}wheel_FL_link"/>
      <axis xyz="0 -1 0"/>
      <limit effort="2.0" velocity="6.0"/>
      <dynamics friction="0.3125" damping="0.1"/>
    </joint>

    <joint name="${joint_prefix}wheel_RL_joint" type="continuous">
      <origin xyz="0.15256 -0.08214 -0.08802" rpy="0 0 0"/>
      <parent link="${link_prefix}rocker_L_link"/>
      <child link="${link_prefix}wheel_RL_link"/>
      <axis xyz="0 -1 0"/>
      <limit effort="2.0" velocity="6.0"/>
      <dynamics friction="0.3125" damping="0.1"/>
    </joint>

    <joint name="${joint_prefix}wheel_FR_joint" type="continuous">
      <origin xyz="0.15256 -0.08214 -0.08802" rpy="0 0 0"/>
      <parent link="${link_prefix}rocker_R_link"/>
      <child link="${link_prefix}wheel_FR_link"/>
      <axis xyz="0 1 0"/>
      <limit effort="2.0" velocity="6.0"/>
      <dynamics friction="0.3125" damping="0.1"/>
    </joint>

    <joint name="${joint_prefix}wheel_RR_joint" type="continuous">
      <origin xyz="-0.15256 -0.08214 -0.08802" rpy="0 0 0"/>
      <parent link="${link_prefix}rocker_R_link"/>
      <child link="${link_prefix}wheel_RR_link"/>
      <axis xyz="0 1 0"/>
      <limit effort="2.0" velocity="6.0"/>
      <dynamics friction="0.3125" damping="0.1"/> 
    </joint>

    <xacro:if value="${default_antenna}">
      <joint name="${joint_prefix}antenna_joint" type="fixed">
        <origin xyz="-0.0052 0.056 -0.0065" rpy="0 0 0"/>
        <parent link="${link_prefix}base_link"/>
        <child link="${link_prefix}antenna_link"/>
      </joint>
    </xacro:if>

    <joint name="${joint_prefix}camera_joint" type="fixed">
      <origin xyz="0.0971 0 -0.0427" rpy="0 0.2094 0"/>
      <parent link="${link_prefix}base_link"/>
      <child link="${link_prefix}camera_frame"/>
    </joint>

    <joint name="${joint_prefix}camera_optical_joint" type="fixed">
      <origin xyz="0 0 0" rpy="-${pi/2} 0.0 -${pi/2}"/>
      <parent link="${link_prefix}camera_frame"/>
      <child link="${link_prefix}camera_optical_frame"/>
    </joint>

    <joint name="${joint_prefix}imu_joint" type="fixed">
      <origin xyz="${imu_translation}" rpy="0 0 0"/>
      <parent link="${link_prefix}base_link"/>
      <child link="${link_prefix}imu_frame"/>
    </joint>

  </xacro:macro>

  <!-- LEO GAZEBO -->

  <xacro:macro name="leo_gazebo"
               params="robot_ns:=''">

    <xacro:property name="link_prefix" value=""/>
    <xacro:if value="${robot_ns != '' and robot_ns != '/'}">
      <xacro:property name="link_prefix" value="${robot_ns}/"/>
    </xacro:if>

    <!-- base ODE properties -->
    <gazebo reference="${link_prefix}base_footprint">
      <kp>1e6</kp>
      <kd>1.0</kd>
      <mu1>0.3</mu1>
      <mu2>0.3</mu2>
      <minDepth>0.003</minDepth>
    </gazebo>

    <gazebo reference="${link_prefix}base_link">
      <kp>1e6</kp>
      <kd>1.0</kd>
      <mu1>0.3</mu1>
      <mu2>0.3</mu2>
      <minDepth>0.003</minDepth>
    </gazebo>

    <!-- rocker ODE properties -->
    <gazebo reference="${link_prefix}rocker_L_link">
      <kp>1e6</kp>
      <kd>1.0</kd>
      <mu1>0.3</mu1>
      <mu2>0.3</mu2>
      <minDepth>0.003</minDepth>
    </gazebo>

    <gazebo reference="${link_prefix}rocker_R_link">
      <kp>1e6</kp>
      <kd>1.0</kd>
      <mu1>0.3</mu1>
      <mu2>0.3</mu2>
      <minDepth>0.003</minDepth>
    </gazebo>
    <!-- wheel ODE properties -->
    <gazebo reference="${link_prefix}wheel_FL_link">
      <kp>1e6</kp>
      <kd>100.0</kd>
      <mu1>3.0</mu1>
      <mu2>1.0</mu2>
      <fdir1>1 0 0</fdir1>
      <minDepth>0.003</minDepth>
    </gazebo>

    <gazebo reference="${link_prefix}wheel_FR_link">
      <kp>1e6</kp>
      <kd>100.0</kd>
      <mu1>3.0</mu1>
      <mu2>1.0</mu2>
      <fdir1>1 0 0</fdir1>
      <minDepth>0.003</minDepth>
    </gazebo>

    <gazebo reference="${link_prefix}wheel_RL_link">
      <kp>1e6</kp>
      <kd>100.0</kd>
      <mu1>3.0</mu1>
      <mu2>1.0</mu2>
      <fdir1>1 0 0</fdir1>
      <minDepth>0.003</minDepth>
    </gazebo>

    <gazebo reference="${link_prefix}wheel_RR_link">
      <kp>1e6</kp>
      <kd>100.0</kd>
      <mu1>3.0</mu1>
      <mu2>1.0</mu2>
      <fdir1>1 0 0</fdir1>
      <minDepth>0.003</minDepth>
    </gazebo>

    <!-- camera -->
    <gazebo reference="${link_prefix}camera_frame">
      <sensor type="camera" name="camera">
        <always_on>true</always_on>
        <update_rate>30.0</update_rate>
        <visualize>false</visualize> 
        <camera name="leo_camera">
          <horizontal_fov>1.9</horizontal_fov>
          <image>
            <width>640</width>
            <height>480</height>
            <format>R8G8B8</format>
          </image>
          <clip>
            <near>0.02</near>
            <far>300</far>
          </clip>
          <noise>
            <type>gaussian</type>
            <mean>0.0</mean>
            <stddev>0.007</stddev>
          </noise>
          <distortion>
            <k1>-0.279817</k1>
            <k2>0.060321</k2>
            <k3>0.000487</k3>
            <p1>0.000310</p1>
            <p2>0.000000</p2>
            <center>0.5 0.5</center>
          </distortion>
        </camera>
        <plugin name="camera_controller" filename="libgazebo_ros_camera.so">
          <ros><namespace>${robot_ns}</namespace></ros>
          <frame_name>camera_optical_frame</frame_name>
        </plugin>
      </sensor>
    </gazebo>

    <!-- rocker differential -->
    <gazebo>
      <plugin name="rocker_differential" filename="libleo_gazebo_differential_plugin.so">
        <jointA>rocker_L_joint</jointA>
        <jointB>rocker_R_joint</jointB>
        <forceConstant>100.0</forceConstant>
      </plugin>
    </gazebo>

    <gazebo reference="${link_prefix}imu_frame">
      <sensor type="imu" name="leo_imu_sensor">
        <update_rate>100</update_rate>
        <plugin filename="libgazebo_ros_imu_sensor.so" name="imu_plugin">
          <robotNamespace>${robot_ns}</robotNamespace>
          <topicName>imu/data_raw</topicName>
          <frameName>${link_prefix}imu_frame</frameName>
          <updateRateHZ>100.0</updateRateHZ>
          <gaussianNoise>0.01</gaussianNoise>
          <initialOrientationAsReference>false</initialOrientationAsReference>
        </plugin>
      </sensor>
    </gazebo>

    <ros2_control name="GazeboSystem" type="system">
      <hardware>
        <plugin>gazebo_ros2_control/GazeboSystem</plugin>
      </hardware>
      <joint name="rocker_L_joint">
        <state_interface name="position"/>
      </joint>
      <joint name="rocker_R_joint">
        <state_interface name="position"/>
      </joint>
      <joint name="wheel_FL_joint">
        <command_interface name="velocity">
          <param name="min">-6</param>
          <param name="max">6</param>
        </command_interface>
        <state_interface name="position"/>
        <state_interface name="velocity"/>
        <state_interface name="effort"/>
      </joint>
      <joint name="wheel_RL_joint">
        <command_interface name="velocity">
          <param name="min">-6</param>
          <param name="max">6</param>
        </command_interface>
        <state_interface name="position"/>
        <state_interface name="velocity"/>
        <state_interface name="effort"/>
      </joint>
      <joint name="wheel_FR_joint">
        <command_interface name="velocity">
          <param name="min">-6</param>
          <param name="max">6</param>
        </command_interface>
        <state_interface name="position"/>
        <state_interface name="velocity"/>
        <state_interface name="effort"/>
      </joint>
      <joint name="wheel_RR_joint">
        <command_interface name="velocity">
          <param name="min">-6</param>
          <param name="max">6</param>
        </command_interface>
        <state_interface name="position"/>
        <state_interface name="velocity"/>
        <state_interface name="effort"/>
      </joint>
    </ros2_control>

    <gazebo>
      <plugin filename="libgazebo_ros2_control.so" name="gazebo_ros2_control">
        <robot_param>robot_description</robot_param>
        <robot_param_node>robot_state_publisher</robot_param_node>
        <parameters>package://leorover_description/config/controllers.yaml</parameters>
      </plugin>
    </gazebo>

  </xacro:macro>

  <xacro:macro name="leo_sim" 
               params="default_antenna:=true 
                       fixed:=false
                       robot_ns:=''">

    <xacro:property name="link_prefix" value=""/>
    <xacro:if value="${robot_ns != '' and robot_ns != '/'}">
      <xacro:property name="link_prefix" value="${robot_ns}/"/>
    </xacro:if>

    <xacro:leo default_antenna="${default_antenna}"
               rockers_fixed="false"
               link_prefix="${link_prefix}"/>

    <xacro:leo_gazebo robot_ns="${robot_ns}"/>

    <xacro:if value="${fixed}">
      <link name="world"/>
      <joint name="fixed" type="fixed">
        <parent link="world"/>
        <child link="${link_prefix}base_footprint"/>
        <origin xyz="0.0 0.0 1.0"/>
      </joint>
    </xacro:if>
  
  </xacro:macro>

</robot>