<?xml version="1.0" ?>
<!-- =================================================================================== -->
<!-- |    This document was autogenerated by xacro from leo.urdf.xacro                 | -->
<!-- |    EDITING THIS FILE BY HAND IS NOT RECOMMENDED                                 | -->
<!-- =================================================================================== -->
<robot name="leo">
  <!-- LEO GAZEBO -->
  <link name="base_footprint"/>
  <link name="base_link">
    <inertial>
      <mass value="1.584994"/>
      <origin xyz="-0.019662 0.011643 -0.031802"/>
      <inertia ixx="0.01042" ixy="0.001177" ixz="-0.0008871" iyy="0.01045" iyz="0.0002226" izz="0.01817"/>
    </inertial>
    <visual>
      <geometry>
        <mesh filename="package://leorover_description/models/Chassis.dae"/>
      </geometry>
    </visual>
    <collision>
      <geometry>
        <mesh filename="package://leorover_description/models/Chassis_outline.stl"/>
      </geometry>
    </collision>
  </link>
  <link name="rocker_L_link">
    <inertial>
      <mass value="1.387336"/>
      <origin xyz="0 0.01346 -0.06506"/>
      <inertia ixx="0.002956" ixy="-0.000001489324" ixz="-0.000008103407" iyy="0.02924" iyz="0.00007112" izz="0.02832"/>
    </inertial>
    <visual>
      <geometry>
        <mesh filename="package://leorover_description/models/Rocker.dae"/>
      </geometry>
    </visual>
    <collision>
      <geometry>
        <mesh filename="package://leorover_description/models/Rocker_outline.stl"/>
      </geometry>
    </collision>
  </link>
  <link name="rocker_R_link">
    <inertial>
      <mass value="1.387336"/>
      <origin xyz="0 0.01346 -0.06506"/>
      <inertia ixx="0.002956" ixy="-0.000001489324" ixz="-0.000008103407" iyy="0.02924" iyz="0.00007112" izz="0.02832"/>
    </inertial>
    <visual>
      <geometry>
        <mesh filename="package://leorover_description/models/Rocker.dae"/>
      </geometry>
    </visual>
    <collision>
      <geometry>
        <mesh filename="package://leorover_description/models/Rocker_outline.stl"/>
      </geometry>
    </collision>
  </link>
  <link name="wheel_FL_link">
    <inertial>
      <mass value="0.283642"/>
      <origin xyz="0 0.030026 0"/>
      <inertia ixx="0.000391" ixy="0.00000123962" ixz="5.52582e-7" iyy="0.0004716" iyz="-0.000002082042" izz="0.000391"/>
    </inertial>
    <visual>
      <geometry>
        <mesh filename="package://leorover_description/models/WheelA.dae"/>
      </geometry>
    </visual>
    <collision>
      <origin rpy="1.5707963267948966 0 0" xyz="0 0.04485 0"/>
      <geometry>
        <cylinder length="0.07" radius="0.057"/>
      </geometry>
    </collision>
    <collision>
      <origin rpy="1.5707963267948966 0 0" xyz="0 0.04485 0"/>
      <geometry>
        <cylinder length="0.04" radius="0.0625"/>
      </geometry>
    </collision>
    <collision>
      <geometry>
        <mesh filename="package://leorover_description/models/Wheel_outline.stl"/>
      </geometry>
    </collision>
  </link>
  <link name="wheel_RL_link">
    <inertial>
      <mass value="0.283642"/>
      <origin xyz="0 0.030026 0"/>
      <inertia ixx="0.000391" ixy="0.00000123962" ixz="5.52582e-7" iyy="0.0004716" iyz="-0.000002082042" izz="0.000391"/>
    </inertial>
    <visual>
      <geometry>
        <mesh filename="package://leorover_description/models/WheelA.dae"/>
      </geometry>
    </visual>
    <collision>
      <origin rpy="1.5707963267948966 0 0" xyz="0 0.04485 0"/>
      <geometry>
        <cylinder length="0.07" radius="0.057"/>
      </geometry>
    </collision>
    <collision>
      <origin rpy="1.5707963267948966 0 0" xyz="0 0.04485 0"/>
      <geometry>
        <cylinder length="0.04" radius="0.0625"/>
      </geometry>
    </collision>
    <collision>
      <geometry>
        <mesh filename="package://leorover_description/models/Wheel_outline.stl"/>
      </geometry>
    </collision>
  </link>
  <link name="wheel_FR_link">
    <inertial>
      <mass value="0.283642"/>
      <origin xyz="0 0.030026 0"/>
      <inertia ixx="0.000391" ixy="0.00000123962" ixz="5.52582e-7" iyy="0.0004716" iyz="-0.000002082042" izz="0.000391"/>
    </inertial>
    <visual>
      <geometry>
        <mesh filename="package://leorover_description/models/WheelB.dae"/>
      </geometry>
    </visual>
    <collision>
      <origin rpy="1.5707963267948966 0 0" xyz="0 0.04485 0"/>
      <geometry>
        <cylinder length="0.07" radius="0.057"/>
      </geometry>
    </collision>
    <collision>
      <origin rpy="1.5707963267948966 0 0" xyz="0 0.04485 0"/>
      <geometry>
        <cylinder length="0.04" radius="0.0625"/>
      </geometry>
    </collision>
    <collision>
      <geometry>
        <mesh filename="package://leorover_description/models/Wheel_outline.stl"/>
      </geometry>
    </collision>
  </link>
  <link name="wheel_RR_link">
    <inertial>
      <mass value="0.283642"/>
      <origin xyz="0 0.030026 0"/>
      <inertia ixx="0.000391" ixy="0.00000123962" ixz="5.52582e-7" iyy="0.0004716" iyz="-0.000002082042" izz="0.000391"/>
    </inertial>
    <visual>
      <geometry>
        <mesh filename="package://leorover_description/models/WheelB.dae"/>
      </geometry>
    </visual>
    <collision>
      <origin rpy="1.5707963267948966 0 0" xyz="0 0.04485 0"/>
      <geometry>
        <cylinder length="0.07" radius="0.057"/>
      </geometry>
    </collision>
    <collision>
      <origin rpy="1.5707963267948966 0 0" xyz="0 0.04485 0"/>
      <geometry>
        <cylinder length="0.04" radius="0.0625"/>
      </geometry>
    </collision>
    <collision>
      <geometry>
        <mesh filename="package://leorover_description/models/Wheel_outline.stl"/>
      </geometry>
    </collision>
  </link>
  <link name="antenna_link">
    <inertial>
      <mass value="0.001237"/>
      <origin xyz="0 0 0.028828"/>
      <inertia ixx="2.5529e-7" ixy="0.0" ixz="0.0" iyy="2.5529e-7" iyz="0.0" izz="1.354e-8"/>
    </inertial>
    <visual>
      <geometry>
        <mesh filename="package://leorover_description/models/Antenna.dae"/>
      </geometry>
    </visual>
    <collision>
      <origin xyz="0 0 0.028"/>
      <geometry>
        <cylinder length="0.056" radius="0.0055"/>
      </geometry>
    </collision>
  </link>
  <link name="camera_frame"/>
  <link name="camera_optical_frame"/>
  <link name="imu_frame"/>
  <!-- JOINTS -->
  <joint name="base_joint" type="fixed">
    <origin rpy="0 0 0" xyz="0 0 0.19783"/>
    <parent link="base_footprint"/>
    <child link="base_link"/>
  </joint>
  <joint name="rocker_L_joint" type="fixed">
    <origin rpy="0 0 3.141592653589793" xyz="0.00263 0.14167 -0.04731"/>
    <parent link="base_link"/>
    <child link="rocker_L_link"/>
    <axis xyz="0 1 0"/>
    <limit effort="100.0" lower="-0.24" upper="0.24" velocity="100.0"/>
    <dynamics damping="0.1" friction="1.0"/>
  </joint>
  <joint name="rocker_R_joint" type="fixed">
    <origin rpy="0 0 0" xyz="0.00263 -0.14167 -0.04731"/>
    <parent link="base_link"/>
    <child link="rocker_R_link"/>
    <axis xyz="0 1 0"/>
    <limit effort="100.0" lower="-0.24" upper="0.24" velocity="100.0"/>
    <dynamics damping="0.1" friction="1.0"/>
    <mimic joint="rocker_L_joint"/>
  </joint>
  <joint name="wheel_FL_joint" type="continuous">
    <origin rpy="0 0 0" xyz="-0.15256 -0.08214 -0.08802"/>
    <parent link="rocker_L_link"/>
    <child link="wheel_FL_link"/>
    <axis xyz="0 -1 0"/>
    <limit effort="2.0" velocity="6.0"/>
    <dynamics damping="0.1" friction="0.3125"/>
  </joint>
  <joint name="wheel_RL_joint" type="continuous">
    <origin rpy="0 0 0" xyz="0.15256 -0.08214 -0.08802"/>
    <parent link="rocker_L_link"/>
    <child link="wheel_RL_link"/>
    <axis xyz="0 -1 0"/>
    <limit effort="2.0" velocity="6.0"/>
    <dynamics damping="0.1" friction="0.3125"/>
  </joint>
  <joint name="wheel_FR_joint" type="continuous">
    <origin rpy="0 0 0" xyz="0.15256 -0.08214 -0.08802"/>
    <parent link="rocker_R_link"/>
    <child link="wheel_FR_link"/>
    <axis xyz="0 1 0"/>
    <limit effort="2.0" velocity="6.0"/>
    <dynamics damping="0.1" friction="0.3125"/>
  </joint>
  <joint name="wheel_RR_joint" type="continuous">
    <origin rpy="0 0 0" xyz="-0.15256 -0.08214 -0.08802"/>
    <parent link="rocker_R_link"/>
    <child link="wheel_RR_link"/>
    <axis xyz="0 1 0"/>
    <limit effort="2.0" velocity="6.0"/>
    <dynamics damping="0.1" friction="0.3125"/>
  </joint>
  <joint name="antenna_joint" type="fixed">
    <origin rpy="0 0 0" xyz="-0.0052 0.056 -0.0065"/>
    <parent link="base_link"/>
    <child link="antenna_link"/>
  </joint>
  <joint name="camera_joint" type="fixed">
    <origin rpy="0 0.2094 0" xyz="0.0971 0 -0.0427"/>
    <parent link="base_link"/>
    <child link="camera_frame"/>
  </joint>
  <joint name="camera_optical_joint" type="fixed">
    <origin rpy="-1.5707963267948966 0.0 -1.5707963267948966" xyz="0 0 0"/>
    <parent link="camera_frame"/>
    <child link="camera_optical_frame"/>
  </joint>
  <joint name="imu_joint" type="fixed">
    <origin rpy="0 0 0" xyz="0.0628 -0.0314 -0.0393"/>
    <parent link="base_link"/>
    <child link="imu_frame"/>
  </joint>
  <!-- 2-segment camera mast with mount for camera -->
  <link name="mast_link">
    <visual>
      <origin rpy="0 0 -1.5707963267948966" xyz="0.006 0.0 0.0"/>
      <geometry>
        <mesh filename="package://leorover_description/models/model_extensions/long_camera_mast.dae"/>
      </geometry>
    </visual>
    <inertial>
      <origin xyz="0.0 0.0 0.1"/>
      <mass value="0.25"/>
      <inertia ixx="0.002956" ixy="-0.000001489324" ixz="-0.000008103407" iyy="0.02924" iyz="0.00007112" izz="0.02832"/>
    </inertial>
    <collision>
      <origin xyz="0.0 0.0 0.1"/>
      <geometry>
        <cylinder length="0.2" radius="0.025"/>
      </geometry>
    </collision>
  </link>
  <joint name="mast_joint" type="fixed">
    <parent link="base_link"/>
    <child link="mast_link"/>
    <origin rpy="0 0 0" xyz="0.024999999999999994 0.0 -0.001"/>
  </joint>
  <link name="camera_mount_link">
    <visual>
      <origin rpy="0 0 1.5707963267948966" xyz="-0.001 0.0 0.0"/>
      <geometry>
        <mesh filename="package://leorover_description/models/model_extensions/camera_mount_fixed_angle_20_degrees_v1.dae"/>
      </geometry>
    </visual>
    <inertial>
      <mass value="0.05"/>
      <inertia ixx="0.01042" ixy="0.001177" ixz="-0.0008871" iyy="0.01045" iyz="0.0002226" izz="0.01817"/>
    </inertial>
  </link>
  <joint name="camera_mount_joint" type="fixed">
    <parent link="mast_link"/>
    <child link="camera_mount_link"/>
    <origin rpy="0 0 0" xyz="0.0025 0.0 0.17"/>
  </joint>
  <link name="mikrotik_antenna_link">
    <inertial>
      <mass value="0.5"/>
      <inertia ixx="0.002956" ixy="-0.000001489324" ixz="-0.000008103407" iyy="0.02924" iyz="0.00007112" izz="0.02832"/>
    </inertial>
    <visual>
      <origin rpy="0 0 1.5707963267948966" xyz="0 0 0"/>
      <geometry>
        <mesh filename="package://leorover_description/models/model_extensions/mikrotik_antenna.dae"/>
      </geometry>
    </visual>
    <collision>
      <origin xyz="0 0 0.08"/>
      <geometry>
        <cylinder length="0.16" radius="0.025"/>
      </geometry>
    </collision>
    <collision>
      <origin xyz="0.0 0.0 0.23"/>
      <geometry>
        <cylinder length="0.3" radius="0.01"/>
      </geometry>
    </collision>
  </link>
  <joint name="mikrotik_antenna_joint" type="fixed">
    <origin rpy="0 0 -0.7853981633974483" xyz="-0.03 0.03 0.03"/>
    <parent link="mast_link"/>
    <child link="mikrotik_antenna_link"/>
  </joint>
  <link name="realsense_link"/>
  <material name="aluminum">
    <color rgba="0.5 0.5 0.5 1"/>
  </material>
  <material name="plastic">
    <color rgba="0.1 0.1 0.1 1"/>
  </material>
  <!-- camera body, with origin at bottom screw mount -->
  <joint name="realsense_camera_joint" type="fixed">
    <origin rpy="0 0 0" xyz="-0.01 0.0 -0.002"/>
    <parent link="realsense_link"/>
    <child link="realsense_camera_bottom_screw_frame"/>
  </joint>
  <link name="realsense_camera_bottom_screw_frame"/>
  <joint name="realsense_camera_link_joint" type="fixed">
    <origin rpy="0 0 0" xyz="0.025195 0.0 0.0145"/>
    <parent link="realsense_camera_bottom_screw_frame"/>
    <child link="realsense_camera_link"/>
  </joint>
  <link name="realsense_camera_link">
    <visual>
      <!-- the mesh origin is at front plate in between the two infrared camera axes -->
      <!-- <origin xyz="${d455_zero_depth_to_glass + d455_glass_to_front} ${-d455_cam_depth_py} 0" rpy="${M_PI/2} 0 ${M_PI/2}"/> -->
      <origin rpy="1.5707963267948966 0 1.5707963267948966" xyz="0 -0.0 0"/>
      <geometry>
        <!-- <box size="${d455_cam_width} ${d455_cam_height} ${d455_cam_depth}"/> -->
        <mesh filename="package://leorover_description/models/model_extensions/d455.stl" scale="0.001 0.001 0.001"/>
        <material name="camera_gray">
          <color rgba="0.2 0.2 0.2 1.0"/>
        </material>
      </geometry>
    </visual>
    <collision>
      <origin rpy="0 0 0" xyz="0 -0.0 0"/>
      <geometry>
        <box size="0.025195 0.124 0.029"/>
      </geometry>
    </collision>
    <inertial>
      <!-- The following are not reliable values, and should not be used for modeling -->
      <mass value="0.072"/>
      <origin xyz="0 0 0"/>
      <inertia ixx="0.003881243" ixy="0.0" ixz="0.0" iyy="0.000498940" iyz="0.0" izz="0.003879257"/>
    </inertial>
  </link>
  <joint name="realsense_joint" type="fixed">
    <origin rpy="0 0.349 0" xyz="0.044 0 0.0635"/>
    <parent link="camera_mount_link"/>
    <child link="realsense_link"/>
  </joint>
  <!-- 
    <link name="/realsense_camera_leo02"/>
    <joint name="${link_prefix}realsense_optical_joint" type="fixed">
      <origin xyz="0.044 0 0.0635" rpy="0 0.349 0"/>
      <parent link="${link_prefix}camera_mount_link"/>
      <child link="/realsense_camera_leo02"/>
    </joint>
-->
  <!-- makita battery 3D printed mount -->
  <link name="makita_battery_mount">
    <visual>
      <origin rpy="0 0 0" xyz="0.0 0.0 0.0"/>
      <!-- ${-pi/2} -->
      <geometry>
        <mesh filename="package://leorover_description/models/model_extensions/makita_battery_mount.dae"/>
      </geometry>
    </visual>
    <inertial>
      <origin xyz="0.0 0.0 0.0"/>
      <mass value="0.2"/>
      <inertia ixx="0.000749" ixy="0" ixz="0" iyy="0.000749" iyz="0" izz="0.000749"/>
    </inertial>
    <collision>
      <origin xyz="0.0 0.0 0.06"/>
      <geometry>
        <box size="0.15 0.15 0.12"/>
      </geometry>
    </collision>
  </link>
  <joint name="makita_battery_mount_joint" type="fixed">
    <origin rpy="0 0 0" xyz="-0.09 0.0 0.0"/>
    <parent link="base_link"/>
    <child link="makita_battery_mount"/>
  </joint>
  <!-- makita battery adapter -->
  <link name="makita_battery_adapter">
    <visual>
      <origin rpy="0 0 0" xyz="0.0 0.0 0.0"/>
      <geometry>
        <mesh filename="package://leorover_description/models/model_extensions/makita_battery_adapter.dae"/>
      </geometry>
    </visual>
    <inertial>
      <origin xyz="0.0 0.0 0.0"/>
      <mass value="0.2"/>
      <inertia ixx="0.000749" ixy="0" ixz="0" iyy="0.000749" iyz="0" izz="0.000749"/>
    </inertial>
    <collision>
      <origin xyz="0.0 0.0 0.012"/>
      <geometry>
        <box size="0.09 0.07 0.025"/>
      </geometry>
    </collision>
  </link>
  <joint name="makita_battery_adapter_joint" type="fixed">
    <origin rpy="0 0 0" xyz="0.0 0.0 0.015"/>
    <parent link="makita_battery_mount"/>
    <child link="makita_battery_adapter"/>
  </joint>
  <!-- makita battery -->
  <link name="makita_battery">
    <visual>
      <origin rpy="0 3.141592653589793 0" xyz="0.0 0.0 0.035"/>
      <geometry>
        <mesh filename="package://leorover_description/models/model_extensions/makita_battery.dae"/>
      </geometry>
    </visual>
    <inertial>
      <origin xyz="0.0 0.0 0.0"/>
      <mass value="0.5"/>
      <inertia ixx="0.00037083" ixy="0" ixz="0" iyy="0.00052083" iyz="0" izz="0.00052083"/>
    </inertial>
    <collision>
      <origin xyz="0.0 0.0 0.01"/>
      <geometry>
        <box size="0.1 0.08 0.04"/>
      </geometry>
    </collision>
  </link>
  <joint name="makita_battery_joint" type="fixed">
    <origin rpy="0 0 0" xyz="-0.005 0.0 0.035"/>
    <parent link="makita_battery_adapter"/>
    <child link="makita_battery"/>
  </joint>
  <!-- entire xavier mount -->
  <link name="xavier_mount">
    <visual>
      <origin rpy="0 0 0" xyz="0.0 0.0 0.0"/>
      <!-- ${-pi/2} -->
      <geometry>
        <mesh filename="package://leorover_description/models/model_extensions/xavier_mount.dae"/>
      </geometry>
    </visual>
    <inertial>
      <origin xyz="0.01 0.0 0.04"/>
      <mass value="0.4"/>
      <inertia ixx="0.00069" ixy="0" ixz="0" iyy="0.00055" iyz="0" izz="0.00055"/>
    </inertial>
    <collision>
      <origin xyz="0.01 0.0 0.04"/>
      <geometry>
        <box size="0.1 0.12 0.08"/>
      </geometry>
    </collision>
  </link>
  <joint name="xavier_mount_joint" type="fixed">
    <origin rpy="0 0 0" xyz="-0.014 0.0 0.12"/>
    <parent link="makita_battery_mount"/>
    <child link="xavier_mount"/>
  </joint>
  <!-- Mount for RP LiDAR -->
  <link name="rp_lidar_mount">
    <visual>
      <origin rpy="0 0 0" xyz="0.0 0.0 0.0"/>
      <!-- ${-pi/2} -->
      <geometry>
        <mesh filename="package://leorover_description/models/model_extensions/rp_lidar_mount.dae"/>
      </geometry>
    </visual>
    <inertial>
      <origin xyz="0.03 0.0 0.008"/>
      <mass value="0.1"/>
      <inertia ixx="0.00027" ixy="0.0" ixz="0.0" iyy="0.00012" iyz="0.0" izz="0.00012"/>
    </inertial>
    <collision>
      <origin xyz="0.03 0.0 0.008"/>
      <geometry>
        <box size="0.12 0.18 0.016"/>
        <!-- <cylinder length="0.2" radius="0.025"/> -->
      </geometry>
    </collision>
  </link>
  <joint name="rp_lidar_mount_joint" type="fixed">
    <origin rpy="0 0 0" xyz="0.0775 0.0 0.0"/>
    <parent link="base_link"/>
    <child link="rp_lidar_mount"/>
  </joint>
  <!-- RP LiDAR -->
  <link name="rp_lidar">
    <visual>
      <origin rpy="0 0 -1.5707963267948966" xyz="0.0 0.0 0.0"/>
      <!-- ${-pi/2} -->
      <geometry>
        <mesh filename="package://leorover_description/models/model_extensions/rp_lidar.dae"/>
      </geometry>
    </visual>
    <inertial>
      <origin xyz="0.03 0.0 0.008"/>
      <mass value="0.1"/>
      <inertia ixx="0.00027" ixy="0.0" ixz="0.0" iyy="0.00012" iyz="0.0" izz="0.00012"/>
    </inertial>
    <collision>
      <origin xyz="0.0 0.0 0.02"/>
      <geometry>
        <cylinder length="0.04" radius="0.04"/>
      </geometry>
    </collision>
  </link>
  <joint name="rp_lidar_joint" type="fixed">
    <origin rpy="0 0 0" xyz="0.05 0.0 0.015"/>
    <parent link="rp_lidar_mount"/>
    <child link="rp_lidar"/>
  </joint>
  <link name="rp_lidar_optical_frame"/>
  <joint name="rp_lidar_optical_frame_joint" type="fixed">
    <origin rpy="0 0 3.141592653589793" xyz="0.0 0.0 0.03"/>
    <parent link="rp_lidar"/>
    <child link="rp_lidar_optical_frame"/>
  </joint>
</robot>
